Workbook

Sheet Instructions
A1: WAREHOUSE EQUIPMENT MAINTENANCE TRACKER - USER GUIDE
A3: OVERVIEW
A4: This tracker provides complete visibility into your warehouse equipment maintenance:
A5: • Equipment Master: Complete list of all equipment with key details
A6: • Maintenance History: Log of all services performed with costs
A7: • PM Schedule: Upcoming preventive maintenance with alerts
A8: • Cost Analysis: Financial dashboard with key metrics
A9: • Invoice Verification: Audit tool to catch billing discrepancies
A11: HOW TO USE
A13: 1. EQUIPMENT MASTER TAB
A14: - Add new equipment as acquired
A15: - Update "Hours/Cycles" regularly
... A66: Review this tracker monthly with your operations team.

Sheet Equipment Master
A1: Equipment ID | B1: Equipment Type | C1: Make/Model | D1: Serial Number | E1: Purchase Date | F1: Purchase Price | G1: Warranty Expiry | H1: Current Status | I1: Location/Zone | J1: Assinged maintainance vendor | K1: PM details | L1: Assigned Operator | M1: Access Code | N1: Hours/Cycles | O1: PM Last Service Date | P1: PM Next Service Due
A2: ECOM 7 | B2: Order Picker Forklift | C2: 520-OPC30TT | D2: 520-15-04181 | H2: VALID | J2: Oklift | K2: quarterly | L2: Licensed Operators | M2: NOT NEEDED | O2: 26/02/2026 | P2: 26/05/2026
A3: ECOM 9 | B3: Electric Pallet Truck | C3: 8400 | D3: 840-06-70324 | H3: VALID | J3: Oklift | K3: quarterly | L3: Licensed Operators | M3: NOT NEEDED | O3: 26/02/2026 | P3: 26/05/2026
A4: ECOM 4 | B4: High Capacity Order Picker | C4: 540-OPC30TT | D4: 540-12-B15231 | E4: 45912 | F4: 14500 | H4: VALID | J4: Oklift | K4: quarterly | L4: Licensed Operators | M4: NOT NEEDED | O4: 26/02/2026 | P4: 26/05/2026
A5: ECOM 3 | B5: High Capacity Order Picker | C5: 540-OPC30TT | D5: 540-12-B15230 | H5: VALID | J5: Oklift | K5: quarterly | L5: Licensed Operators | M5: NOT NEEDED | O5: 26/02/2026 | P5: 26/05/2026
A6: ECOM 5 | B6: High Capacity Order Picker | C6: 540-OPC30TT | D6: 540-12-B15235 | E6: 45912 | F6: 14500 | H6: VALID | J6: Oklift | K6: quarterly | L6: Licensed Operators | M6: NOT NEEDED | O6: 26/02/2026 | P6: 26/05/2026
A7: ECOM 6 | B7: Counter Balance | C7: 8FBE2GU | D7: 14455 | E7: 45912 | F7: 25900 | H7: VALID | J7: Oklift | K7: quarterly | L7: Licensed Operators | M7: NOT NEEDED | O7: 26/02/2026 | P7: 26/05/2026
A8: ECOM 8 | B8: Turret Truck | C8: EASI DR30TT | D8: EZ-D.04.30478 | H8: VALID | J8: Oklift | K8: quarterly | L8: Licensed Operators | M8: NOT NEEDED | O8: 26/02/2026 | P8: 26/05/2026
A9: ECOM 1 | B9: Turret Truck | C9: 752-R45TT | D9: 752-20-AD78747 | E9: 45812 | F9: 35450 | H9: VALID | J9: Oklift | K9: quarterly | L9: Licensed Operators | M9: NOT NEEDED | O9: 26/02/2026 | P9: 26/05/2026
A10: ECOM 2 | B10: Turret Truck | C10: 752-R45TT | D10: 752-20-AD78713 | E10: 45812 | F10: 35450 | H10: VALID | J10: Oklift | K10: quarterly | L10: Licensed Operators | M10: NOT NEEDED | O10: 26/02/2026 | P10: 26/05/2026
A11: ECOM 11 | B11: Floor Scrubber | C11: xr40c v2.0 | D11: 151445 | E11: 45922 | F11: 23559 | H11: VALID | J11: Oklift | K11: quarterly | L11: Licensed Operators | M11: NOT NEEDED | O11: 26/02/2026 | P11: 26/05/2026
A12: ECOM 10 | B12: Electric Walkie | C12: 840-FRE601 | D12: 840-06-66956 | H12: VALID | J12: Oklift | K12: quarterly | L12: Licensed Operators | M12: NOT NEEDED
A13: Needs # | B13: Bailer Compactor | E13: 46006 | F13: 4520

Sheet Maintenance History 2025
A1: Service ID/Work Order # | B1: Equipment ID | C1: Service Date | D1: Service Type | E1: Service Provider | F1: Issue Reported | G1: Work Performed | H1: Parts Replaced | I1: Labor Hours | J1: Parts Cost | K1: Labor Cost | L1: Total Cost | M1: Invoice Number | N1: Next Service Due | O1: Technician Name | P1: Downtime (Hours) | Q1: Approved by
L2: =J2+K2 -> 0
L3: =J3+K3 -> 0
L4: =J4+K4 -> 0
L5: =J5+K5 -> 0
L6: =J6+K6 -> 0
L7: =J7+K7 -> 0
L8: =J8+K8 -> 0
L9: =J9+K9 -> 0
L10: =J10+K10 -> 0
L11: =J11+K11 -> 0
L12: =J12+K12 -> 0
L13: =J13+K13 -> 0
... L26: =J26+K26 -> 0

Sheet PM Schedule 2026-2027
A1: Equipment ID | B1: Equipment Type | C1: Service Frequency (Days) | D1: Last Service Date | E1: Next Service Due | F1: Annual Inspection Due | G1: Days Until Due | H1: Status | I1: Estimated Cost | J1: Service Provider | K1: 1st service Cycle | L1: 2nd service Cycle | M1: 3rd service Cycle | N1: 4th service Cycle | O1: Notes
A2: ECOM 7 | B2: Order Picker Forklift | C2: Quarterly | D2: 46079 | E2: 46168 | F2: 26/02/2027 | G2: =E2-TODAY() -> 55 | H2: VALID | I2: 150 | J2: Oklift | K2: 26/02/2026 | L2: 26/05/2026 | M2: 26/08/2026 | N2: 26/11/2026
A3: ECOM 9 | B3: Electric Pallet Truck | C3: Quarterly | D3: 46079 | E3: 46168 | F3: 26/02/2027 | G3: =E3-TODAY() -> 55 | H3: VALID | I3: 150 | J3: Oklift | K3: 26/02/2026 | L3: 26/05/2026 | M3: 26/08/2026 | N3: 26/11/2026
A4: ECOM 4 | B4: High Capacity Order Picker | C4: Quarterly | D4: 46079 | E4: 46168 | F4: 26/02/2027 | G4: =E4-TODAY() -> 55 | H4: VALID | I4: 150 | J4: Oklift | K4: 26/02/2026 | L4: 26/05/2026 | M4: 26/08/2026 | N4: 26/11/2026
A5: ECOM 3 | B5: High Capacity Order Picker | C5: Quarterly | D5: 46079 | E5: 46168 | F5: 26/02/2027 | G5: =E5-TODAY() -> 55 | H5: VALID | I5: 150 | J5: Oklift | K5: 26/02/2026 | L5: 26/05/2026 | M5: 26/08/2026 | N5: 26/11/2026
A6: ECOM 5 | B6: High Capacity Order Picker | C6: Quarterly | D6: 46079 | E6: 46168 | F6: 26/02/2027 | G6: =E6-TODAY() -> 55 | H6: VALID | I6: 150 | J6: Oklift | K6: 26/02/2026 | L6: 26/05/2026 | M6: 26/08/2026 | N6: 26/11/2026
A7: ECOM 6 | B7: Electric Forklift Truck | C7: Quarterly | D7: 46079 | E7: 46168 | F7: 26/02/2027 | G7: =E7-TODAY() -> 55 | H7: VALID | I7: 150 | J7: Oklift | K7: 26/02/2026 | L7: 26/05/2026 | M7: 26/08/2026 | N7: 26/11/2026
A8: ECOM 8 | B8: Turret Truck | C8: Quarterly | D8: 46079 | E8: 46168 | F8: 26/02/2027 | G8: =E8-TODAY() -> 55 | H8: VALID | I8: 150 | J8: Oklift | K8: 26/02/2026 | L8: 26/05/2026 | M8: 26/08/2026 | N8: 26/11/2026 | O8: Failed Annual Inspection (serviced)
A9: ECOM 1 | B9: Turret Truck | C9: Quarterly | D9: 46079 | E9: 46168 | F9: 26/02/2027 | G9: =E9-TODAY() -> 55 | H9: VALID | I9: 150 | J9: Oklift | K9: 26/02/2026 | L9: 26/05/2026 | M9: 26/08/2026 | N9: 26/11/2026
A10: ECOM 2 | B10: Turret Truck | C10: Quarterly | D10: 46079 | E10: 46168 | F10: 26/02/2027 | G10: =E10-TODAY() -> 55 | H10: VALID | I10: 150 | J10: Oklift | K10: 26/02/2026 | L10: 26/05/2026 | M10: 26/08/2026 | N10: 26/11/2026 | O10: Failed Annual Inspection (serviced)
A11: ECOM 11 | B11: Floor Scrubber | C11: Quarterly | D11: 46079 | E11: 46168 | F11: 26/02/2027 | G11: =E11-TODAY() -> 55 | H11: VALID | I11: 150 | J11: Oklift | K11: 26/02/2026 | L11: 26/05/2026 | M11: 26/08/2026 | N11: 26/11/2026 | O11: Failed Annual Inspection (serviced by warranty)
A12: ECOM 10 | B12: Electric Walkie | C12: Quarterly | D12: 46079 | E12: 46168 | F12: 26/02/2027 | G12: =E12-TODAY() -> 55 | H12: VALID | I12: 150 | J12: Oklift | K12: 26/02/2026 | L12: 26/05/2026 | M12: 26/08/2026 | N12: 26/11/2026 | O12: Battery needed service (serviced)
G13: =E13-TODAY() -> -46113 | H13: =IF(G13<0,"OVERDUE",IF(G13<=7,"URGENT",IF(G13<=30,"UPCOMING","OK"))) -> OVERDUE
G14: =E14-TODAY() -> -46113 | H14: =IF(G14<0,"OVERDUE",IF(G14<=7,"URGENT",IF(G14<=30,"UPCOMING","OK"))) -> OVERDUE
G15: =E15-TODAY() -> -46113 | H15: =IF(G15<0,"OVERDUE",IF(G15<=7,"URGENT",IF(G15<=30,"UPCOMING","OK"))) -> OVERDUE
G16: =E16-TODAY() -> -46113 | H16: =IF(G16<0,"OVERDUE",IF(G16<=7,"URGENT",IF(G16<=30,"UPCOMING","OK"))) -> OVERDUE
G17: =E17-TODAY() -> -46113 | H17: =IF(G17<0,"OVERDUE",IF(G17<=7,"URGENT",IF(G17<=30,"UPCOMING","OK"))) -> OVERDUE
G18: =E18-TODAY() -> -46113 | H18: =IF(G18<0,"OVERDUE",IF(G18<=7,"URGENT",IF(G18<=30,"UPCOMING","OK"))) -> OVERDUE
G19: =E19-TODAY() -> -46113 | H19: =IF(G19<0,"OVERDUE",IF(G19<=7,"URGENT",IF(G19<=30,"UPCOMING","OK"))) -> OVERDUE
G20: =E20-TODAY() -> -46113 | H20: =IF(G20<0,"OVERDUE",IF(G20<=7,"URGENT",IF(G20<=30,"UPCOMING","OK"))) -> OVERDUE
G21: =E21-TODAY() -> -46113 | H21: =IF(G21<0,"OVERDUE",IF(G21<=7,"URGENT",IF(G21<=30,"UPCOMING","OK"))) -> OVERDUE

Sheet Dashboard
A1: Month | B1: Asset # | C1: Total Maintenance Cost | D1: PM Cost | E1: Breakdown Cost | F1: Overdue Assets,=COUNTIF('Upcoming Maintenance'!E:E,"Overdue"),0 | G1: Due Soon Assets,=COUNTIF('Upcoming Maintenance'!E:E,"Due Soon"),0 | H1: PM Compliance % | I1: Avg Cost per Asset | J1: Top Cost Driver (Asset ID)
H2: Preventive vs Corrective Ratio,=COUNTIF('Maintenance Log'!D:D,"Preventive")/COUNTA('Maintenance Log'!D:D),100%
Q3: B | R3: Formula / Comment
Q4: Ecom Logistics – Maintenance Dashboard | R4: (Bold heading)
Q5: Metric | R5: Value / Formula (paste into column B)
Q6: Total Assets | R6: 1
Q7: Total Maintenance Cost | R7: #REF!
Q8: Preventive Maintenance Cost | R8: =SUMIFS('Maintenance Log'!L:L,'Maintenance Log'!D:D,"PM / Breakdown") (adjust wording if your “Maintenance Type” says “PM / Preventive”)
Q9: Breakdown Cost | R9: #REF!
Q10: Overdue Assets | R10: #REF!
Q11: Due Soon Assets | R11: #REF!
Q12: PM Compliance % | R12: 0
Q13: Avg Cost per Asset | R13: 0
Q14: Preventive vs Corrective Ratio % | R14: 0
Q15: (Blank row for spacing)
Q16: Chart 1: Maintenance Cost by Month | R16: → create Pivot Table from Maintenance Log (Rows = Date grouped by Month, Values = Cost), insert Line Chart
Q17: Chart 2: Preventive vs Breakdown Cost | R17: → source same Pivot, Rows = Maintenance Type, Values = Cost, insert Pie Chart
Q18: Chart 3: Cost by Equipment Type | R18: → combine Maintenance Log + Asset Register via Asset ID; create Pivot Table (group by Equipment Type), insert Bar Chart

Sheet Cost Analysis
A1: MONTHLY MAINTENANCE COST SUMMARY
A3: Month | B3: Preventive Cost | C3: Repair Cost | D3: Total Cost | E3: Service Count | F3: Avg Cost per Service | G3: Overdue Assets,=COUNTIF('Upcoming Maintenance'!E:E,"Overdue"),0
D4: =B4+C4 -> 0 | F4: =D4/E4 -> #DIV/0!
D5: =B5+C5 -> 0 | F5: =D5/E5 -> #DIV/0!
D6: =B6+C6 -> 0 | F6: =D6/E6 -> #DIV/0!
A9: COST BY EQUIPMENT TYPE
A11: Equipment Type | B11: Total Maintenance Cost | C11: Service Count | D11: Avg Cost per Service | E11: Total Downtime (Hrs)
A12: Reach Truck | B12: =SUMIF('Maintenance History 2025'!B:B,"RT-*",'Maintenance History 2025'!L:L) -> 0 | C12: =COUNTIF('Maintenance History 2025'!B:B,"RT-*") -> 0 | D12: =B12/C12 -> #DIV/0! | E12: =SUMIF('Maintenance History 2025'!B:B,"RT-*",'Maintenance History 2025'!P:P) -> 0
A13: Order Picker | B13: =SUMIF('Maintenance History 2025'!B:B,"OP-*",'Maintenance History 2025'!L:L) -> 0 | C13: =COUNTIF('Maintenance History 2025'!B:B,"OP-*") -> 0 | D13: =B13/C13 -> #DIV/0! | E13: =SUMIF('Maintenance History 2025'!B:B,"OP-*",'Maintenance History 2025'!P:P) -> 0
A14: Forklift | B14: =SUMIF('Maintenance History 2025'!B:B,"FK-*",'Maintenance History 2025'!L:L) -> 0 | C14: =COUNTIF('Maintenance History 2025'!B:B,"FK-*") -> 0 | D14: =B14/C14 -> #DIV/0! | E14: =SUMIF('Maintenance History 2025'!B:B,"FK-*",'Maintenance History 2025'!P:P) -> 0
A17: SERVICE PROVIDER COMPARISON
A19: Service Provider | B19: Total Billed | C19: Service Count | D19: Avg per Service | E19: Total Downtime (Hrs)
A20: ABC Maintenance Co. | B20: =SUMIF('Maintenance History 2025'!E:E,"ABC Maintenance Co.",'Maintenance History 2025'!L:L) -> 0 | C20: =COUNTIF('Maintenance History 2025'!E:E,"ABC Maintenance Co.") -> 0 | D20: =B20/C20 -> #DIV/0! | E20: =SUMIF('Maintenance History 2025'!E:E,"ABC Maintenance Co.",'Maintenance History 2025'!P:P) -> 0
A21: XYZ Equipment Services | B21: =SUMIF('Maintenance History 2025'!E:E,"XYZ Equipment Services",'Maintenance History 2025'!L:L) -> 0 | C21: =COUNTIF('Maintenance History 2025'!E:E,"XYZ Equipment Services") -> 0 | D21: =B21/C21 -> #DIV/0! | E21: =SUMIF('Maintenance History 2025'!E:E,"XYZ Equipment Services",'Maintenance History 2025'!P:P) -> 0
A24: KEY METRICS
A26: Total YTD Maintenance Spend: | B26: =SUM('Maintenance History 2025'!L:L) -> 0
A27: Average Service Cost: | B27: =AVERAGE('Maintenance History 2025'!L:L) -> 0
A28: Total Equipment Downtime (Hrs): | B28: =SUM('Maintenance History 2025'!P:P) -> 0
A29: Preventive vs Repair Ratio: | B29: =COUNTIF('Maintenance History 2025'!D:D,"Preventive")/COUNTIF('Maintenance History 2025'!D:D,"Repair") -> #DIV/0! | C29: (Higher is better)

Sheet Invoice Verification
A1: INVOICE VERIFICATION & BILLING AUDIT
A3: Invoice Date | B3: Invoice Number | C3: Equipment ID | D3: Service Provider | E3: Billed Amount | F3: Expected Amount | G3: Variance | H3: Variance % | I3: Status | J3: Approved by | K3: Notes/Discrepancies
A4: 09/06/2025 | B4: 1105 | C4: ECOM 6 | D4: Okay Lift LTD | E4: 169.5 | G4: =E4-F4 -> 169.5 | H4: =IF(F4=0,0,G4/F4) -> 0 | I4: =IF(ABS(H4)>0.1,"FLAG","OK") -> OK | K4: preventative maintenance
A5: 02/09/2025 | B5: 1375 | C5: NA | D5: Okay Lift LTD | E5: 7825.25 | F5: 7825 | G5: =E5-F5 -> 0.25 | H5: =IF(F5=0,0,G5/F5) -> 3.1948882e-05 | I5: =IF(ABS(H5)>0.1,"FLAG","OK") -> OK | K5: Transportation discounted and Trade-in lowered equipment sale
A6: 09/09/2025 | B6: 1387 | C6: ECOM 8 | D6: Okay Lift LTD | E6: 1017 | F6: 1017 | G6: =SUM(E6:E11)-SUM(F6:F11) -> 0 | H6: =IF(F6=0,0,G6/F6) -> 0 | I6: =IF(ABS(H6)>0.1,"FLAG","OK") -> OK | K6: preventative maintenance
A7: 09/09/2025 | B7: 1387 | C7: ECOM 7 | D7: Okay Lift LTD | H7: =IF(F7=0,0,G7/F7) -> 0 | I7: =IF(ABS(H7)>0.1,"FLAG","OK") -> OK | K7: preventative maintenance
A8: 09/09/2025 | B8: 1387 | C8: NA | D8: Okay Lift LTD | H8: =IF(F8=0,0,G8/F8) -> 0 | I8: =IF(ABS(H8)>0.1,"FLAG","OK") -> OK | K8: preventative maintenance
A9: 09/09/2025 | B9: 1387 | C9: ECOM 9 | D9: Okay Lift LTD | H9: =IF(F9=0,0,G9/F9) -> 0 | I9: =IF(ABS(H9)>0.1,"FLAG","OK") -> OK | K9: preventative maintenance
A10: 09/09/2025 | B10: 1387 | C10: NA | D10: Okay Lift LTD | H10: =IF(F10=0,0,G10/F10) -> 0 | I10: =IF(ABS(H10)>0.1,"FLAG","OK") -> OK | K10: preventative maintenance
A11: 09/09/2025 | B11: 1387 | C11: ECOM 3 | D11: Okay Lift LTD | H11: =IF(F11=0,0,G11/F11) -> 0 | I11: =IF(ABS(H11)>0.1,"FLAG","OK") -> OK | K11: preventative maintenance
A12: 29/09/2025 | B12: 1441 | C12: ECOM 8 | D12: Okay Lift LTD | E12: 747.01 | F12: 747 | G12: =E12-F12 -> 0.01 | H12: =IF(F12=0,0,G12/F12) -> 1.3386881e-05 | I12: =IF(ABS(H12)>0.1,"FLAG","OK") -> OK | K12: additional fee on replacement of drive tired and press on charges
A13: 09/09/2025 | B13: 1417 | C13: NA | D13: Okay Lift LTD | E13: 1067.49 | G13: =E13-F13 -> 1067.49 | H13: =IF(F13=0,0,G13/F13) -> 0 | I13: =IF(ABS(H13)>0.1,"FLAG","OK") -> OK | K13: purchase of wheels with labor, potential damaged bearing, consumables
A14: 09/09/2025 | B14: 1416 | C14: ECOM 9 | D14: Okay Lift LTD | E14: 1332.95 | G14: =E14-F14 -> 1332.95 | H14: =IF(F14=0,0,G14/F14) -> 0 | I14: =IF(ABS(H14)>0.1,"FLAG","OK") -> OK | K14: purchase of wheels, bearings, consumables, drive wheel (major replacement), labor
A15: 09/09/2025 | B15: 1415 | C15: NA | D15: Okay Lift LTD | E15: 1155.94 | G15: =E15-F15 -> 1155.94 | H15: =IF(F15=0,0,G15/F15) -> 0 | I15: =IF(ABS(H15)>0.1,"FLAG","OK") -> OK | K15: purchase of load and caster wheels + bearings, and replacement
A16: 09/09/2025 | B16: 1414 | C16: ECOM 8 | D16: Okay Lift LTD | E16: 1494.49 | G16: =E16-F16 -> 1494.49 | H16: =IF(F16=0,0,G16/F16) -> 0 | I16: =IF(ABS(H16)>0.1,"FLAG","OK") -> OK | K16: purchase of load wheels + bearings + consumables, plate, replacement of steer motor brushes, DIAGNOSIS OF HORN???
A17: 29/09/2025 | B17: 1435 | C17: NA | D17: Okay Lift LTD | E17: 0 | F17: 50172 | G17: =E17-F17 -> -50172 | H17: =IF(F17=0,0,G17/F17) -> -1 | I17: =IF(ABS(H17)>0.1,"FLAG","OK") -> FLAG | K17: purchase of new equipment (including trade-in discount)
A18: 16/10/2025 | B18: 1471 | C18: NA | D18: Okay Lift LTD | E18: 0 | F18: 2204 | G18: =E18-F18 -> -2204 | H18: =IF(F18=0,0,G18/F18) -> -1 | I18: =IF(ABS(H18)>0.1,"FLAG","OK") -> FLAG | K18: transportation of 2 order pickers machines and counter balance
A19: 23/10/2025 | B19: 1483 | C19: ECOM 1 | D19: Okay Lift LTD | E19: 0 | F19: 598 | G19: =E19-F19 -> -598 | H19: =IF(F19=0,0,G19/F19) -> -1 | I19: =IF(ABS(H19)>0.1,"FLAG","OK") -> FLAG | K19: purchase of load wheels + bearings + consumables
A20: 09/06/2025 | B20: 1438 | C20: ECOM 7 | D20: Okay Lift LTD | E20: 169.5 | F20: 170 | G20: =E20-F20 -> -0.5 | H20: =IF(F20=0,0,G20/F20) -> -0.0029411765 | I20: =IF(ABS(H20)>0.1,"FLAG","OK") -> OK | K20: preventative maintenance
A21: 01/12/2025 | B21: 1552 | C21: NA | D21: Okay Lift LTD | E21: 152.38 | F21: 152 | G21: =E21-F21 -> 0.38 | H21: =IF(F21=0,0,G21/F21) -> 0.0025 | I21: =IF(ABS(H21)>0.1,"FLAG","OK") -> OK | K21: no mention of machine
A22: 01/12/2025 | B22: 1553 | C22: ECOM 8 | D22: Okay Lift LTD | E22: 378.19 | F22: 378.19 | G22: =E22-F22 -> 0 | H22: =IF(F22=0,0,G22/F22) -> 0 | I22: =IF(ABS(H22)>0.1,"FLAG","OK") -> OK | K22: HORN mentioned again for same machine, only 3 months ago!!!!
A23: 04/12/2025 | B23: 1558 | C23: NA | D23: Okay Lift LTD | E23: 196.12 | F23: 196.12 | G23: =E23-F23 -> 0 | H23: =IF(F23=0,0,G23/F23) -> 0 | I23: =IF(ABS(H23)>0.1,"FLAG","OK") -> OK | K23: purchase of charger, replaced with the purchased circuit breaker only for it to immediately break
A24: 27/12/2025 | B24: 1589 | C24: NA | D24: Okay Lift LTD | E24: 1695 | G24: =E24-F24 -> 1695 | H24: =IF(F24=0,0,G24/F24) -> 0 | I24: =IF(ABS(H24)>0.1,"FLAG","OK") -> OK | K24: purhase of parts
A25: 27/12/2025 | B25: 1586 | C25: ECOM 9 | D25: Okay Lift LTD | E25: 645.04 | G25: =E25-F25 -> 645.04 | H25: =IF(F25=0,0,G25/F25) -> 0 | I25: =IF(ABS(H25)>0.1,"FLAG","OK") -> OK | K25: purchase of battery with replacement and parts
A26: 09/01/2026 | B26: 1609 | C26: NA | D26: Okay Lift LTD | E26: 0 | F26: 202 | G26: =E26-F26 -> -202 | H26: =IF(F26=0,0,G26/F26) -> -1 | I26: =IF(ABS(H26)>0.1,"FLAG","OK") -> FLAG | K26: purchae of battery with replpacement
A27: 04/12/2025 | B27: 1560 | C27: ECOM 6 | D27: Okay Lift LTD | E27: 1884 | F27: 2165 | G27: =E27-F27 -> -281 | H27: =IF(F27=0,0,G27/F27) -> -0.12979215 | I27: =IF(ABS(H27)>0.1,"FLAG","OK") -> FLAG | K27: purchase of backrest for ECOM 6 + labor
A28: 15/12/2025 | B28: 1566 | C28: ALL | D28: Okay Lift LTD | E28: 0 | F28: 7718 | G28: =E28-F28 -> -7718 | H28: =IF(F28=0,0,G28/F28) -> -1 | I28: =IF(ABS(H28)>0.1,"FLAG","OK") -> FLAG | K28: preventative maintenance
A29: 27/12/2025 | B29: 1593 | C29: ECOM 1 | D29: Okay Lift LTD | E29: 0 | F29: 470 | G29: =E29-F29 -> -470 | H29: =IF(F29=0,0,G29/F29) -> -1 | I29: =IF(ABS(H29)>0.1,"FLAG","OK") -> FLAG | K29: installation of camera
A30: 17/02/2025 | B30: 1257 | C30: NA | D30: Okay Lift LTD | E30: 1125.28 | F30: 1125.28 | G30: =E30-F30 -> 0 | H30: =IF(F30=0,0,G30/F30) -> 0 | I30: =IF(ABS(H30)>0.1,"FLAG","OK") -> OK
A31: 1702/2025 | B31: 1259 | C31: NA | D31: Okay Lift LTD | E31: 1282.65 | F31: 1283 | G31: =E31-F31 -> -0.35 | H31: =IF(F31=0,0,G31/F31) -> -0.00027279813 | I31: =IF(ABS(H31)>0.1,"FLAG","OK") -> OK
A32: 17/02/2025 | B32: 1259 | C32: NA | D32: Okay Lift LTD | E32: 1449.9 | F32: 1450 | G32: =E32-F32 -> -0.1 | H32: =IF(F32=0,0,G32/F32) -> -6.8965517e-05 | I32: =IF(ABS(H32)>0.1,"FLAG","OK") -> OK
A33: 17/02/2025 | B33: 1260 | C33: NA | D33: Okay Lift LTD | E33: 990.81 | F33: 991 | G33: =E33-F33 -> -0.19 | H33: =IF(F33=0,0,G33/F33) -> -0.00019172553 | I33: =IF(ABS(H33)>0.1,"FLAG","OK") -> OK | V33: =SUM(F16:F19,F26:F29,F50) -> 64566
A34: 17/02/2025 | B34: 1261 | C34: NA | D34: Okay Lift LTD | E34: 726.72 | F34: 727 | G34: =E34-F34 -> -0.28 | H34: =IF(F34=0,0,G34/F34) -> -0.00038514443 | I34: =IF(ABS(H34)>0.1,"FLAG","OK") -> OK
A35: 17/02/2025 | B35: 1262 | C35: NA | D35: Okay Lift LTD | E35: 1186.5 | F35: 1186.5 | G35: =E35-F35 -> 0 | H35: =IF(F35=0,0,G35/F35) -> 0 | I35: =IF(ABS(H35)>0.1,"FLAG","OK") -> OK
A36: 20/03/2025 | B36: 1288 | C36: NA | D36: Okay Lift LTD | E36: 326.57 | F36: 327 | G36: =E36-F36 -> -0.43 | H36: =IF(F36=0,0,G36/F36) -> -0.0013149847 | I36: =IF(ABS(H36)>0.1,"FLAG","OK") -> OK
A37: 20/03/2025 | B37: 1291 | C37: NA | D37: Okay Lift LTD | E37: 1097.91 | F37: 1098 | G37: =E37-F37 -> -0.09 | H37: =IF(F37=0,0,G37/F37) -> -8.1967213e-05 | I37: =IF(ABS(H37)>0.1,"FLAG","OK") -> OK
A38: 23/03/2025 | B38: 1092 | C38: NA | D38: Okay Lift LTD | E38: 1328.8 | F38: 1329 | G38: =E38-F38 -> -0.2 | H38: =IF(F38=0,0,G38/F38) -> -0.00015048909 | I38: =IF(ABS(H38)>0.1,"FLAG","OK") -> OK
A39: 23/03/2025 | B39: 1144 | C39: NA | D39: Okay Lift LTD | E39: 1162.77 | F39: 1163 | G39: =E39-F39 -> -0.23 | H39: =IF(F39=0,0,G39/F39) -> -0.0001977644 | I39: =IF(ABS(H39)>0.1,"FLAG","OK") -> OK
A40: 23/03/2025 | B40: 1145 | C40: NA | D40: Okay Lift LTD | E40: 185 | F40: 185 | G40: =E40-F40 -> 0 | H40: =IF(F40=0,0,G40/F40) -> 0 | I40: =IF(ABS(H40)>0.1,"FLAG","OK") -> OK
A41: 09/06/2025 | B41: 1437 | C41: NA | D41: Okay Lift LTD | E41: 169.5 | F41: 170 | G41: =E41-F41 -> -0.5 | H41: =IF(F41=0,0,G41/F41) -> -0.0029411765 | I41: =IF(ABS(H41)>0.1,"FLAG","OK") -> OK
...

Sheet Action Plan
A1: Date | B1: stakeholders | C1: Action plan
A2: 25-02-2026 | B2: Yara Salameh , Omar Laz, Mohid Dard, Marisa Brunetta | C2: 1- Plot into excel comparison of costs 2- Email Gurbhej regarding 'no sticker' equipment 3- Get cost of booklets for daily machinery checkup 4- Find out who is paying for machinery licenses 5. Explore options for stickers visibility for machinery rather than using paint. 6. Plates rather than stickers for ECOM numbers.
B7: Companies for sticker visibility | C7: Responded
B8: Brady Canada | C8: pending
B9: Signarama | C9: pending
B10: Diamond Line Painting | C10: visit 9:30 AM 05/03/26
B11: GTAproepoxy | C11: pending
